<?xml version="1.0"?>
<sdf version="1.9">
  <model name="warthog_02m_pro_4wd_chassis">
    <pose>0 0 0 0 0 0</pose>
    <static>false</static>

    <link name="base_link">
      <pose>0 0 0 0 0 0</pose>
      <inertial>
        <mass>120.000</mass>
        <inertia>
          <ixx>18.0</ixx>
          <iyy>24.0</iyy>
          <izz>30.0</izz>
        </inertia>
      </inertial>
      <visual name="cad_visual">
        <geometry>
          <mesh>
            <uri>model://warthog_02m_pro_4wd_chassis/meshes/chassis_visual.stl</uri>
            <scale>0.001 0.001 0.001</scale>
          </mesh>
        </geometry>
        <material>
          <diffuse>0.45 0.48 0.48 1</diffuse>
          <specular>0.15 0.15 0.15 1</specular>
        </material>
      </visual>
      <collision name="body_collision">
        <pose>0 0 0.480 0 0 0</pose>
        <geometry>
          <box>
            <size>1.200 0.780 0.320</size>
          </box>
        </geometry>
      </collision>
    </link>

    <link name="front_left_wheel_link">
      <pose>0.343 0.500 0.285 -1.57079632679 0 0</pose>
      <inertial>
        <mass>12.000</mass>
        <inertia>
          <ixx>0.380</ixx>
          <iyy>0.380</iyy>
          <izz>0.070</izz>
        </inertia>
      </inertial>
      <collision name="collision">
        <geometry>
          <cylinder>
            <radius>0.285</radius>
            <length>0.220</length>
          </cylinder>
        </geometry>
        <surface>
          <friction>
            <ode>
              <mu>1.2</mu>
              <mu2>1.2</mu2>
              <fdir1>0 0 1</fdir1>
            </ode>
          </friction>
        </surface>
      </collision>
    </link>
    <link name="front_right_wheel_link">
      <pose>0.343 -0.500 0.285 -1.57079632679 0 0</pose>
      <inertial>
        <mass>12.000</mass>
        <inertia>
          <ixx>0.380</ixx>
          <iyy>0.380</iyy>
          <izz>0.070</izz>
        </inertia>
      </inertial>
      <collision name="collision">
        <geometry>
          <cylinder>
            <radius>0.285</radius>
            <length>0.220</length>
          </cylinder>
        </geometry>
        <surface>
          <friction>
            <ode>
              <mu>1.2</mu>
              <mu2>1.2</mu2>
              <fdir1>0 0 1</fdir1>
            </ode>
          </friction>
        </surface>
      </collision>
    </link>
    <link name="rear_left_wheel_link">
      <pose>-0.498 0.500 0.285 -1.57079632679 0 0</pose>
      <inertial>
        <mass>12.000</mass>
        <inertia>
          <ixx>0.380</ixx>
          <iyy>0.380</iyy>
          <izz>0.070</izz>
        </inertia>
      </inertial>
      <collision name="collision">
        <geometry>
          <cylinder>
            <radius>0.285</radius>
            <length>0.220</length>
          </cylinder>
        </geometry>
        <surface>
          <friction>
            <ode>
              <mu>1.2</mu>
              <mu2>1.2</mu2>
              <fdir1>0 0 1</fdir1>
            </ode>
          </friction>
        </surface>
      </collision>
    </link>
    <link name="rear_right_wheel_link">
      <pose>-0.498 -0.500 0.285 -1.57079632679 0 0</pose>
      <inertial>
        <mass>12.000</mass>
        <inertia>
          <ixx>0.380</ixx>
          <iyy>0.380</iyy>
          <izz>0.070</izz>
        </inertia>
      </inertial>
      <collision name="collision">
        <geometry>
          <cylinder>
            <radius>0.285</radius>
            <length>0.220</length>
          </cylinder>
        </geometry>
        <surface>
          <friction>
            <ode>
              <mu>1.2</mu>
              <mu2>1.2</mu2>
              <fdir1>0 0 1</fdir1>
            </ode>
          </friction>
        </surface>
      </collision>
    </link>

    <joint name="front_left_wheel_joint" type="revolute">
      <parent>base_link</parent>
      <child>front_left_wheel_link</child>
      <axis>
        <xyz>0 0 1</xyz>
        <limit>
          <lower>-1e16</lower>
          <upper>1e16</upper>
        </limit>
        <dynamics>
          <damping>0.2</damping>
        </dynamics>
      </axis>
    </joint>
    <joint name="front_right_wheel_joint" type="revolute">
      <parent>base_link</parent>
      <child>front_right_wheel_link</child>
      <axis>
        <xyz>0 0 1</xyz>
        <limit>
          <lower>-1e16</lower>
          <upper>1e16</upper>
        </limit>
        <dynamics>
          <damping>0.2</damping>
        </dynamics>
      </axis>
    </joint>
    <joint name="rear_left_wheel_joint" type="revolute">
      <parent>base_link</parent>
      <child>rear_left_wheel_link</child>
      <axis>
        <xyz>0 0 1</xyz>
        <limit>
          <lower>-1e16</lower>
          <upper>1e16</upper>
        </limit>
        <dynamics>
          <damping>0.2</damping>
        </dynamics>
      </axis>
    </joint>
    <joint name="rear_right_wheel_joint" type="revolute">
      <parent>base_link</parent>
      <child>rear_right_wheel_link</child>
      <axis>
        <xyz>0 0 1</xyz>
        <limit>
          <lower>-1e16</lower>
          <upper>1e16</upper>
        </limit>
        <dynamics>
          <damping>0.2</damping>
        </dynamics>
      </axis>
    </joint>

    <plugin filename="gz-sim-diff-drive-system" name="gz::sim::systems::DiffDrive">
      <left_joint>front_left_wheel_joint</left_joint>
      <left_joint>rear_left_wheel_joint</left_joint>
      <right_joint>front_right_wheel_joint</right_joint>
      <right_joint>rear_right_wheel_joint</right_joint>
      <wheel_separation>1.000</wheel_separation>
      <wheel_radius>0.285</wheel_radius>
      <max_linear_velocity>0.30</max_linear_velocity>
      <max_linear_acceleration>0.50</max_linear_acceleration>
      <max_angular_velocity>0.80</max_angular_velocity>
      <max_angular_acceleration>1.00</max_angular_acceleration>
      <topic>/cmd_vel</topic>
      <odom_topic>/odom</odom_topic>
      <tf_topic>/tf</tf_topic>
      <frame_id>odom</frame_id>
      <child_frame_id>base_link</child_frame_id>
      <odom_publish_frequency>50</odom_publish_frequency>
    </plugin>
  </model>
</sdf>
